============================= test session starts ==============================
platform linux -- Python 3.9.2, pytest-6.2.2, py-1.10.0, pluggy-0.13.1
rootdir: /home/stidsem4/iut/2021/controle/eric.han/c16_03
collected 7 items

test_16_03.py ..F....                                                    [100%]

=================================== FAILURES ===================================
_____________________________ Test1603sute.test_4 ______________________________

self = <c16_03.test_16_03.Test1603sute testMethod=test_4>

    def test_4(self):
        try:
>           from main import moyenne_tuples
E           ImportError: cannot import name 'moyenne_tuples' from 'main' (/home/stidsem4/iut/2021/controle/eric.han/main.py)

test_16_03.py:16: ImportError

During handling of the above exception, another exception occurred:

self = <c16_03.test_16_03.Test1603sute testMethod=test_4>

    def test_4(self):
        try:
            from main import moyenne_tuples
        except ImportError:
            try:
>               from .main import moyenne_tuple as moyenne_tuples
E               ImportError: cannot import name 'moyenne_tuple' from 'c16_03.main' (/home/stidsem4/iut/2021/controle/eric.han/c16_03/main.py)

test_16_03.py:19: ImportError

During handling of the above exception, another exception occurred:

self = <c16_03.test_16_03.Test1603sute testMethod=test_4>

    def test_4(self):
        try:
            from main import moyenne_tuples
        except ImportError:
            try:
                from .main import moyenne_tuple as moyenne_tuples
            except ImportError:
>               assert False, "moyenne_tuples non définie"
E               AssertionError: moyenne_tuples non définie
E               assert False

test_16_03.py:21: AssertionError
=========================== short test summary info ============================
FAILED test_16_03.py::Test1603sute::test_4 - AssertionError: moyenne_tuples n...
========================= 1 failed, 6 passed in 0.09s ==========================
